# Error Processing Log - 20241023_202643

Total errors to process: 30


Processing row 1 of 30

==================================================
Processing Error Pattern 4
Description: Incorrect handling of rare edge cases
Files to modify: ['project/api/llama_stack/providers/adapters/inference/ollama/ollama.py']
==================================================
Executing command: python error-bot/bot.py project/api/llama_stack/providers/adapters/inference/ollama/ollama.py 4 --commit
Bot output:
Starting main function with file_paths: ['project/api/llama_stack/providers/adapters/inference/ollama/ollama.py'], error_number: 4, commit_to_branch: True, multi_file: False
Processing single file: project/api/llama_stack/providers/adapters/inference/ollama/ollama.py with error number: 4
Sending request to Anthropic model...
Received diff content from Anthropic for file: project/api/llama_stack/providers/adapters/inference/ollama/ollama.py
Diff for error pattern 4 has been saved to error-bot/code-test/diff_ollama_py.patch
Full output has been saved to error-bot/code-test/full_output_ollama_py.txt
Patch applied successfully for file: project/api/llama_stack/providers/adapters/inference/ollama/ollama.py
Creating new git branch: error-4-api
Successfully created branch: error-4-api
Committing changes to file: /Users/nehal/Documents/Code/Golden-PR-Dataset/project/api/llama_stack/providers/adapters/inference/ollama/ollama.py
Changes to be committed:
.../api/llama_stack/providers/adapters/inference/ollama/ollama.py   | 6 ++----
 1 file changed, 2 insertions(+), 4 deletions(-)
Successfully committed changes: [main 72172dfd] Add error pattern 4 in ollama.py
 1 file changed, 2 insertions(+), 4 deletions(-)
Error pattern 4 has been added to /Users/nehal/Documents/Code/Golden-PR-Dataset/project/api/llama_stack/providers/adapters/inference/ollama/ollama.py in branch error-4-api
Last commit: 72172dfd Add error pattern 4 in ollama.py


==================================================
BRANCH CREATED: error-4-api
==================================================

Modified files:
  - project/api/llama_stack/providers/adapters/inference/ollama/ollama.py

Diff files:
  - error-bot/code-test/diff_ollama_py.patch

Full output files:
  - error-bot/code-test/full_output_ollama_py.txt

Last commit:
  72172dfd Add error pattern 4 in ollama.py
User input: 

Processing row 2 of 30

==================================================
Processing Error Pattern 18
Description: Subtle issues with caching mechanisms
Files to modify: ['project/api/llama_stack/providers/adapters/memory/pgvector/pgvector.py']
==================================================
Executing command: python error-bot/bot.py project/api/llama_stack/providers/adapters/memory/pgvector/pgvector.py 18 --commit
Bot output:
Starting main function with file_paths: ['project/api/llama_stack/providers/adapters/memory/pgvector/pgvector.py'], error_number: 18, commit_to_branch: True, multi_file: False
Processing single file: project/api/llama_stack/providers/adapters/memory/pgvector/pgvector.py with error number: 18
Sending request to Anthropic model...
Received diff content from Anthropic for file: project/api/llama_stack/providers/adapters/memory/pgvector/pgvector.py
Diff for error pattern 18 has been saved to error-bot/code-test/diff_pgvector_py.patch
Full output has been saved to error-bot/code-test/full_output_pgvector_py.txt
Patch applied successfully for file: project/api/llama_stack/providers/adapters/memory/pgvector/pgvector.py
Creating new git branch: error-18-api
Successfully created branch: error-18-api
Committing changes to file: /Users/nehal/Documents/Code/Golden-PR-Dataset/project/api/llama_stack/providers/adapters/memory/pgvector/pgvector.py
Changes to be committed:
.../llama_stack/providers/adapters/memory/pgvector/pgvector.py   | 9 +++++++--
 1 file changed, 7 insertions(+), 2 deletions(-)
Successfully committed changes: [main 047dee09] Add error pattern 18 in pgvector.py
 1 file changed, 7 insertions(+), 2 deletions(-)
Error pattern 18 has been added to /Users/nehal/Documents/Code/Golden-PR-Dataset/project/api/llama_stack/providers/adapters/memory/pgvector/pgvector.py in branch error-18-api
Last commit: 047dee09 Add error pattern 18 in pgvector.py


==================================================
BRANCH CREATED: error-18-api
==================================================

Modified files:
  - project/api/llama_stack/providers/adapters/memory/pgvector/pgvector.py

Diff files:
  - error-bot/code-test/diff_pgvector_py.patch

Full output files:
  - error-bot/code-test/full_output_pgvector_py.txt

Last commit:
  047dee09 Add error pattern 18 in pgvector.py
User input: 

Processing row 3 of 30

==================================================
Processing Error Pattern 5
Description: Logical errors in complex conditional statements
Files to modify: ['project/api/llama_stack/providers/impls/meta_reference/agents/agents.py']
==================================================
Executing command: python error-bot/bot.py project/api/llama_stack/providers/impls/meta_reference/agents/agents.py 5 --commit
Bot output:
Starting main function with file_paths: ['project/api/llama_stack/providers/impls/meta_reference/agents/agents.py'], error_number: 5, commit_to_branch: True, multi_file: False
Processing single file: project/api/llama_stack/providers/impls/meta_reference/agents/agents.py with error number: 5
Sending request to Anthropic model...
Received diff content from Anthropic for file: project/api/llama_stack/providers/impls/meta_reference/agents/agents.py
Diff for error pattern 5 has been saved to error-bot/code-test/diff_agents_py.patch
Full output has been saved to error-bot/code-test/full_output_agents_py.txt
Patch applied successfully for file: project/api/llama_stack/providers/impls/meta_reference/agents/agents.py
Creating new git branch: error-5-api
Successfully created branch: error-5-api
Committing changes to file: /Users/nehal/Documents/Code/Golden-PR-Dataset/project/api/llama_stack/providers/impls/meta_reference/agents/agents.py
Changes to be committed:
project/api/llama_stack/providers/impls/meta_reference/agents/agents.py | 2 +-
 1 file changed, 1 insertion(+), 1 deletion(-)
Successfully committed changes: [main a019a610] Add error pattern 5 in agents.py
 1 file changed, 1 insertion(+), 1 deletion(-)
Error pattern 5 has been added to /Users/nehal/Documents/Code/Golden-PR-Dataset/project/api/llama_stack/providers/impls/meta_reference/agents/agents.py in branch error-5-api
Last commit: a019a610 Add error pattern 5 in agents.py


==================================================
BRANCH CREATED: error-5-api
==================================================

Modified files:
  - project/api/llama_stack/providers/impls/meta_reference/agents/agents.py

Diff files:
  - error-bot/code-test/diff_agents_py.patch

Full output files:
  - error-bot/code-test/full_output_agents_py.txt

Last commit:
  a019a610 Add error pattern 5 in agents.py
User input: 

Processing row 4 of 30

==================================================
Processing Error Pattern 37
Description: Incorrect assumptions about API behavior
Files to modify: ['project/api/llama_stack/apis/inference/inference.py']
==================================================
Executing command: python error-bot/bot.py project/api/llama_stack/apis/inference/inference.py 37 --commit
Bot output:
Starting main function with file_paths: ['project/api/llama_stack/apis/inference/inference.py'], error_number: 37, commit_to_branch: True, multi_file: False
Processing single file: project/api/llama_stack/apis/inference/inference.py with error number: 37
Sending request to Anthropic model...
Received diff content from Anthropic for file: project/api/llama_stack/apis/inference/inference.py
Diff for error pattern 37 has been saved to error-bot/code-test/diff_inference_py.patch
Full output has been saved to error-bot/code-test/full_output_inference_py.txt
Patch applied successfully for file: project/api/llama_stack/apis/inference/inference.py
Creating new git branch: error-37-api
Successfully created branch: error-37-api
Committing changes to file: /Users/nehal/Documents/Code/Golden-PR-Dataset/project/api/llama_stack/apis/inference/inference.py
Changes to be committed:
project/api/llama_stack/apis/inference/inference.py | 5 ++---
 1 file changed, 2 insertions(+), 3 deletions(-)
Successfully committed changes: [main 25b5d329] Add error pattern 37 in inference.py
 1 file changed, 2 insertions(+), 3 deletions(-)
Error pattern 37 has been added to /Users/nehal/Documents/Code/Golden-PR-Dataset/project/api/llama_stack/apis/inference/inference.py in branch error-37-api
Last commit: 25b5d329 Add error pattern 37 in inference.py


==================================================
BRANCH CREATED: error-37-api
==================================================

Modified files:
  - project/api/llama_stack/apis/inference/inference.py

Diff files:
  - error-bot/code-test/diff_inference_py.patch

Full output files:
  - error-bot/code-test/full_output_inference_py.txt

Last commit:
  25b5d329 Add error pattern 37 in inference.py
User input: 

Processing row 5 of 30

==================================================
Processing Error Pattern 3
Description: Race conditions in multi-threaded code
Files to modify: ['project/api/llama_stack/providers/adapters/memory/qdrant/qdrant.py', 'project/api/llama_stack/providers/utils/memory/vector_store.py']
==================================================
Executing command: python error-bot/bot.py project/api/llama_stack/providers/adapters/memory/qdrant/qdrant.py project/api/llama_stack/providers/utils/memory/vector_store.py 3 --commit --multi-file
Error processing row 5: Command '['python', 'error-bot/bot.py', 'project/api/llama_stack/providers/adapters/memory/qdrant/qdrant.py', 'project/api/llama_stack/providers/utils/memory/vector_store.py', '3', '--commit', '--multi-file']' returned non-zero exit status 1.
Error output:
Starting main function with file_paths: ['project/api/llama_stack/providers/adapters/memory/qdrant/qdrant.py', 'project/api/llama_stack/providers/utils/memory/vector_store.py'], error_number: 3, commit_to_branch: True, multi_file: True
Handling multi-file errors for files: ['project/api/llama_stack/providers/adapters/memory/qdrant/qdrant.py', 'project/api/llama_stack/providers/utils/memory/vector_store.py'] with error number: 3

User input: 

Processing row 6 of 30

==================================================
Processing Error Pattern 6
Description: Incorrect implementations of design patterns
Files to modify: ['project/api/llama_stack/apis/agents/agents.py', 'project/api/llama_stack/apis/agents/client.py', 'project/api/llama_stack/providers/impls/meta_reference/agents/agents.py']
==================================================
Executing command: python error-bot/bot.py project/api/llama_stack/apis/agents/agents.py project/api/llama_stack/apis/agents/client.py project/api/llama_stack/providers/impls/meta_reference/agents/agents.py 6 --commit --multi-file
Bot output:
Starting main function with file_paths: ['project/api/llama_stack/apis/agents/agents.py', 'project/api/llama_stack/apis/agents/client.py', 'project/api/llama_stack/providers/impls/meta_reference/agents/agents.py'], error_number: 6, commit_to_branch: True, multi_file: True
Handling multi-file errors for files: ['project/api/llama_stack/apis/agents/agents.py', 'project/api/llama_stack/apis/agents/client.py', 'project/api/llama_stack/providers/impls/meta_reference/agents/agents.py'] with error number: 6
Creating messages for Anthropic model...
Sending request to Anthropic model...
Error: Could not find diff tags in the response for file: project/api/llama_stack/apis/agents/agents.py
Error: Could not find diff tags in the response for file: project/api/llama_stack/apis/agents/client.py
Received diff content from Anthropic for file: project/api/llama_stack/providers/impls/meta_reference/agents/agents.py
Diff for error pattern 6 has been saved to error-bot/code-test/diff_agents_py.patch
Full output has been saved to error-bot/code-test/full_output_agents_py.txt
Patch applied successfully for file: project/api/llama_stack/providers/impls/meta_reference/agents/agents.py
Modified content has been saved to /Users/nehal/Documents/Code/Golden-PR-Dataset/project/api/llama_stack/providers/impls/meta_reference/agents/agents.py
Creating new git branch: error-6-api
Successfully created branch: error-6-api
Committing changes to file: project/api/llama_stack/providers/impls/meta_reference/agents/agents.py
Changes to be committed:
.../providers/impls/meta_reference/agents/agents.py          | 12 +++++++-----
 1 file changed, 7 insertions(+), 5 deletions(-)
Successfully committed changes: [main 26029470] Add error pattern 6 to multiple files
 1 file changed, 7 insertions(+), 5 deletions(-)
Error pattern 6 has been added to 1 files in branch error-6-api
Last commit: 26029470 Add error pattern 6 to multiple files


==================================================
BRANCH CREATED: error-6-api
==================================================

Modified files:
  - project/api/llama_stack/apis/agents/agents.py
  - project/api/llama_stack/apis/agents/client.py
  - project/api/llama_stack/providers/impls/meta_reference/agents/agents.py

Diff files:
  - error-bot/code-test/diff_agents_py.patch
  - error-bot/code-test/diff_client_py.patch
  - error-bot/code-test/diff_agents_py.patch

Full output files:
  - error-bot/code-test/full_output_agents_py.txt
  - error-bot/code-test/full_output_client_py.txt
  - error-bot/code-test/full_output_agents_py.txt

Last commit:
  26029470 Add error pattern 6 to multiple files
User input: 

Processing row 7 of 30

==================================================
Processing Error Pattern 17
Description: Improper handling of concurrent database transactions
Files to modify: ['project/api/llama_stack/distribution/server/server.py', 'project/api/llama_stack/distribution/routers/routing_tables.py']
==================================================
Executing command: python error-bot/bot.py project/api/llama_stack/distribution/server/server.py project/api/llama_stack/distribution/routers/routing_tables.py 17 --commit --multi-file
Bot output:
Starting main function with file_paths: ['project/api/llama_stack/distribution/server/server.py', 'project/api/llama_stack/distribution/routers/routing_tables.py'], error_number: 17, commit_to_branch: True, multi_file: True
Handling multi-file errors for files: ['project/api/llama_stack/distribution/server/server.py', 'project/api/llama_stack/distribution/routers/routing_tables.py'] with error number: 17
Creating messages for Anthropic model...
Sending request to Anthropic model...
Received diff content from Anthropic for file: project/api/llama_stack/distribution/server/server.py
Diff for error pattern 17 has been saved to error-bot/code-test/diff_server_py.patch
Full output has been saved to error-bot/code-test/full_output_server_py.txt
Patch applied successfully for file: project/api/llama_stack/distribution/server/server.py
Modified content has been saved to /Users/nehal/Documents/Code/Golden-PR-Dataset/project/api/llama_stack/distribution/server/server.py
Received diff content from Anthropic for file: project/api/llama_stack/distribution/routers/routing_tables.py
Diff for error pattern 17 has been saved to error-bot/code-test/diff_routing_tables_py.patch
Full output has been saved to error-bot/code-test/full_output_routing_tables_py.txt
Patch applied successfully for file: project/api/llama_stack/distribution/routers/routing_tables.py
Modified content has been saved to /Users/nehal/Documents/Code/Golden-PR-Dataset/project/api/llama_stack/distribution/routers/routing_tables.py
Creating new git branch: error-17-api
Successfully created branch: error-17-api
Committing changes to file: project/api/llama_stack/distribution/server/server.py
Changes to be committed:
project/api/llama_stack/distribution/server/server.py | 2 +-
 1 file changed, 1 insertion(+), 1 deletion(-)
Successfully committed changes: [main 36124927] Add error pattern 17 to multiple files
 1 file changed, 1 insertion(+), 1 deletion(-)
Committing changes to file: project/api/llama_stack/distribution/routers/routing_tables.py
Changes to be committed:
.../api/llama_stack/distribution/routers/routing_tables.py | 14 +++-----------
 1 file changed, 3 insertions(+), 11 deletions(-)
Successfully committed changes: [main 8bb256e0] Add error pattern 17 to multiple files
 1 file changed, 3 insertions(+), 11 deletions(-)
Error pattern 17 has been added to 2 files in branch error-17-api
Last commit: 8bb256e0 Add error pattern 17 to multiple files


==================================================
BRANCH CREATED: error-17-api
==================================================

Modified files:
  - project/api/llama_stack/distribution/server/server.py
  - project/api/llama_stack/distribution/routers/routing_tables.py

Diff files:
  - error-bot/code-test/diff_server_py.patch
  - error-bot/code-test/diff_routing_tables_py.patch

Full output files:
  - error-bot/code-test/full_output_server_py.txt
  - error-bot/code-test/full_output_routing_tables_py.txt

Last commit:
  8bb256e0 Add error pattern 17 to multiple files
User input: 

Processing row 8 of 30

==================================================
Processing Error Pattern 30
Description: Subtle issues with asynchronous code
Files to modify: ['project/api/llama_stack/providers/adapters/inference/fireworks', 'project/api/llama_stack/providers/adapters/inference/databricks/databricks.py', 'project/api/llama_stack/apis/inference/inference.py']
==================================================
Executing command: python error-bot/bot.py project/api/llama_stack/providers/adapters/inference/fireworks project/api/llama_stack/providers/adapters/inference/databricks/databricks.py project/api/llama_stack/apis/inference/inference.py 30 --commit --multi-file
Error processing row 8: Command '['python', 'error-bot/bot.py', 'project/api/llama_stack/providers/adapters/inference/fireworks', 'project/api/llama_stack/providers/adapters/inference/databricks/databricks.py', 'project/api/llama_stack/apis/inference/inference.py', '30', '--commit', '--multi-file']' returned non-zero exit status 1.
Error output:
Starting main function with file_paths: ['project/api/llama_stack/providers/adapters/inference/fireworks', 'project/api/llama_stack/providers/adapters/inference/databricks/databricks.py', 'project/api/llama_stack/apis/inference/inference.py'], error_number: 30, commit_to_branch: True, multi_file: True
Handling multi-file errors for files: ['project/api/llama_stack/providers/adapters/inference/fireworks', 'project/api/llama_stack/providers/adapters/inference/databricks/databricks.py', 'project/api/llama_stack/apis/inference/inference.py'] with error number: 30

User input: 

Processing row 9 of 30

==================================================
Processing Error Pattern 40
Description: Incorrect handling of null or undefined values in complex scenarios
Files to modify: ['project/api/llama_stack/providers/adapters/safety/together/together.py', 'project/api/llama_stack/apis/agents/agents.py']
==================================================
Executing command: python error-bot/bot.py project/api/llama_stack/providers/adapters/safety/together/together.py project/api/llama_stack/apis/agents/agents.py 40 --commit --multi-file
Bot output:
Starting main function with file_paths: ['project/api/llama_stack/providers/adapters/safety/together/together.py', 'project/api/llama_stack/apis/agents/agents.py'], error_number: 40, commit_to_branch: True, multi_file: True
Handling multi-file errors for files: ['project/api/llama_stack/providers/adapters/safety/together/together.py', 'project/api/llama_stack/apis/agents/agents.py'] with error number: 40
Creating messages for Anthropic model...
Sending request to Anthropic model...
Received diff content from Anthropic for file: project/api/llama_stack/providers/adapters/safety/together/together.py
Diff for error pattern 40 has been saved to error-bot/code-test/diff_together_py.patch
Full output has been saved to error-bot/code-test/full_output_together_py.txt
Patch applied successfully for file: project/api/llama_stack/providers/adapters/safety/together/together.py
Modified content has been saved to /Users/nehal/Documents/Code/Golden-PR-Dataset/project/api/llama_stack/providers/adapters/safety/together/together.py
Received diff content from Anthropic for file: project/api/llama_stack/apis/agents/agents.py
Diff for error pattern 40 has been saved to error-bot/code-test/diff_agents_py.patch
Full output has been saved to error-bot/code-test/full_output_agents_py.txt
Patch applied successfully for file: project/api/llama_stack/apis/agents/agents.py
Modified content has been saved to /Users/nehal/Documents/Code/Golden-PR-Dataset/project/api/llama_stack/apis/agents/agents.py
Creating new git branch: error-40-api
Successfully created branch: error-40-api
Committing changes to file: project/api/llama_stack/providers/adapters/safety/together/together.py
Changes to be committed:
.../api/llama_stack/providers/adapters/safety/together/together.py  | 6 +++---
 1 file changed, 3 insertions(+), 3 deletions(-)
Successfully committed changes: [main 08c56ef7] Add error pattern 40 to multiple files
 1 file changed, 3 insertions(+), 3 deletions(-)
Committing changes to file: project/api/llama_stack/apis/agents/agents.py
Changes to be committed:
project/api/llama_stack/apis/agents/agents.py | 10 +++++-----
 1 file changed, 5 insertions(+), 5 deletions(-)
Successfully committed changes: [main 8fe8fb1d] Add error pattern 40 to multiple files
 1 file changed, 5 insertions(+), 5 deletions(-)
Error pattern 40 has been added to 2 files in branch error-40-api
Last commit: 8fe8fb1d Add error pattern 40 to multiple files


==================================================
BRANCH CREATED: error-40-api
==================================================

Modified files:
  - project/api/llama_stack/providers/adapters/safety/together/together.py
  - project/api/llama_stack/apis/agents/agents.py

Diff files:
  - error-bot/code-test/diff_together_py.patch
  - error-bot/code-test/diff_agents_py.patch

Full output files:
  - error-bot/code-test/full_output_together_py.txt
  - error-bot/code-test/full_output_agents_py.txt

Last commit:
  8fe8fb1d Add error pattern 40 to multiple files
User input: 

Processing row 10 of 30

==================================================
Processing Error Pattern 19
Description: Incorrect implementations of complex mathematical formulas
Files to modify: ['project/api/llama_stack/apis/scoring_functions/scoring_functions.py', 'project/api/llama_stack/apis/inference/inference.py', 'project/api/llama_stack/providers/impls/meta_reference/agents/agents.py']
==================================================
Executing command: python error-bot/bot.py project/api/llama_stack/apis/scoring_functions/scoring_functions.py project/api/llama_stack/apis/inference/inference.py project/api/llama_stack/providers/impls/meta_reference/agents/agents.py 19 --commit --multi-file
Error processing row 10: Command '['python', 'error-bot/bot.py', 'project/api/llama_stack/apis/scoring_functions/scoring_functions.py', 'project/api/llama_stack/apis/inference/inference.py', 'project/api/llama_stack/providers/impls/meta_reference/agents/agents.py', '19', '--commit', '--multi-file']' returned non-zero exit status 1.
Error output:
Starting main function with file_paths: ['project/api/llama_stack/apis/scoring_functions/scoring_functions.py', 'project/api/llama_stack/apis/inference/inference.py', 'project/api/llama_stack/providers/impls/meta_reference/agents/agents.py'], error_number: 19, commit_to_branch: True, multi_file: True
Handling multi-file errors for files: ['project/api/llama_stack/apis/scoring_functions/scoring_functions.py', 'project/api/llama_stack/apis/inference/inference.py', 'project/api/llama_stack/providers/impls/meta_reference/agents/agents.py'] with error number: 19

User input: 

Processing row 11 of 30

==================================================
Processing Error Pattern 15
Description: Subtle issues with character encoding and internationalization
Files to modify: ['project/api/llama_stack/apis/datasetio/datasetio.py', 'project/api/llama_stack/cli/model/prompt_format.py', 'project/api/llama_stack/providers/adapters/memory/pgvector/pgvector.py']
==================================================
Executing command: python error-bot/bot.py project/api/llama_stack/apis/datasetio/datasetio.py project/api/llama_stack/cli/model/prompt_format.py project/api/llama_stack/providers/adapters/memory/pgvector/pgvector.py 15 --commit --multi-file
Error processing row 11: Command '['python', 'error-bot/bot.py', 'project/api/llama_stack/apis/datasetio/datasetio.py', 'project/api/llama_stack/cli/model/prompt_format.py', 'project/api/llama_stack/providers/adapters/memory/pgvector/pgvector.py', '15', '--commit', '--multi-file']' returned non-zero exit status 1.
Error output:
Starting main function with file_paths: ['project/api/llama_stack/apis/datasetio/datasetio.py', 'project/api/llama_stack/cli/model/prompt_format.py', 'project/api/llama_stack/providers/adapters/memory/pgvector/pgvector.py'], error_number: 15, commit_to_branch: True, multi_file: True
Handling multi-file errors for files: ['project/api/llama_stack/apis/datasetio/datasetio.py', 'project/api/llama_stack/cli/model/prompt_format.py', 'project/api/llama_stack/providers/adapters/memory/pgvector/pgvector.py'] with error number: 15

User input: 

Processing row 12 of 30

==================================================
Processing Error Pattern 43
Description: Incorrect handling of long-running processes
Files to modify: ['project/api/llama_stack/cli/stack/run.py', 'project/api/llama_stack/distribution/configure.py', 'project/api/llama_stack/distribution/server/server.py', 'project/api/llama_stack/distribution/utils/prompt_for_config.py']
==================================================
Executing command: python error-bot/bot.py project/api/llama_stack/cli/stack/run.py project/api/llama_stack/distribution/configure.py project/api/llama_stack/distribution/server/server.py project/api/llama_stack/distribution/utils/prompt_for_config.py 43 --commit --multi-file
Bot output:
Starting main function with file_paths: ['project/api/llama_stack/cli/stack/run.py', 'project/api/llama_stack/distribution/configure.py', 'project/api/llama_stack/distribution/server/server.py', 'project/api/llama_stack/distribution/utils/prompt_for_config.py'], error_number: 43, commit_to_branch: True, multi_file: True
Handling multi-file errors for files: ['project/api/llama_stack/cli/stack/run.py', 'project/api/llama_stack/distribution/configure.py', 'project/api/llama_stack/distribution/server/server.py', 'project/api/llama_stack/distribution/utils/prompt_for_config.py'] with error number: 43
Creating messages for Anthropic model...
Sending request to Anthropic model...
Received diff content from Anthropic for file: project/api/llama_stack/cli/stack/run.py
Diff for error pattern 43 has been saved to error-bot/code-test/diff_run_py.patch
Full output has been saved to error-bot/code-test/full_output_run_py.txt
Error: Failed to apply the patch for file: project/api/llama_stack/cli/stack/run.py
Error: Could not find diff tags in the response for file: project/api/llama_stack/distribution/configure.py
Received diff content from Anthropic for file: project/api/llama_stack/distribution/server/server.py
Diff for error pattern 43 has been saved to error-bot/code-test/diff_server_py.patch
Full output has been saved to error-bot/code-test/full_output_server_py.txt
Patch applied successfully for file: project/api/llama_stack/distribution/server/server.py
Modified content has been saved to /Users/nehal/Documents/Code/Golden-PR-Dataset/project/api/llama_stack/distribution/server/server.py
Error: Could not find diff tags in the response for file: project/api/llama_stack/distribution/utils/prompt_for_config.py
Creating new git branch: error-43-api
Successfully created branch: error-43-api
Committing changes to file: project/api/llama_stack/distribution/server/server.py
Changes to be committed:
project/api/llama_stack/distribution/server/server.py | 14 ++------------
 1 file changed, 2 insertions(+), 12 deletions(-)
Successfully committed changes: [main 6e315227] Add error pattern 43 to multiple files
 1 file changed, 2 insertions(+), 12 deletions(-)
Error pattern 43 has been added to 1 files in branch error-43-api
Last commit: 6e315227 Add error pattern 43 to multiple files


==================================================
BRANCH CREATED: error-43-api
==================================================

Modified files:
  - project/api/llama_stack/cli/stack/run.py
  - project/api/llama_stack/distribution/configure.py
  - project/api/llama_stack/distribution/server/server.py
  - project/api/llama_stack/distribution/utils/prompt_for_config.py

Diff files:
  - error-bot/code-test/diff_run_py.patch
  - error-bot/code-test/diff_configure_py.patch
  - error-bot/code-test/diff_server_py.patch
  - error-bot/code-test/diff_prompt_for_config_py.patch

Full output files:
  - error-bot/code-test/full_output_run_py.txt
  - error-bot/code-test/full_output_configure_py.txt
  - error-bot/code-test/full_output_server_py.txt
  - error-bot/code-test/full_output_prompt_for_config_py.txt

Last commit:
  6e315227 Add error pattern 43 to multiple files
User input: 

Processing row 13 of 30

==================================================
Processing Error Pattern 20
Description: Unintended consequences of code optimizations
Files to modify: ['project/api/llama_stack/apis/batch_inference/batch_inference.py', 'project/api/llama_stack/apis/inference/inference.py', 'project/api/llama_stack/providers/adapters/telemetry/opentelemetry/opentelemetry.py']
==================================================
Executing command: python error-bot/bot.py project/api/llama_stack/apis/batch_inference/batch_inference.py project/api/llama_stack/apis/inference/inference.py project/api/llama_stack/providers/adapters/telemetry/opentelemetry/opentelemetry.py 20 --commit --multi-file
Bot output:
Starting main function with file_paths: ['project/api/llama_stack/apis/batch_inference/batch_inference.py', 'project/api/llama_stack/apis/inference/inference.py', 'project/api/llama_stack/providers/adapters/telemetry/opentelemetry/opentelemetry.py'], error_number: 20, commit_to_branch: True, multi_file: True
Handling multi-file errors for files: ['project/api/llama_stack/apis/batch_inference/batch_inference.py', 'project/api/llama_stack/apis/inference/inference.py', 'project/api/llama_stack/providers/adapters/telemetry/opentelemetry/opentelemetry.py'] with error number: 20
Creating messages for Anthropic model...
Sending request to Anthropic model...
Received diff content from Anthropic for file: project/api/llama_stack/apis/batch_inference/batch_inference.py
Diff for error pattern 20 has been saved to error-bot/code-test/diff_batch_inference_py.patch
Full output has been saved to error-bot/code-test/full_output_batch_inference_py.txt
Patch applied successfully for file: project/api/llama_stack/apis/batch_inference/batch_inference.py
Modified content has been saved to /Users/nehal/Documents/Code/Golden-PR-Dataset/project/api/llama_stack/apis/batch_inference/batch_inference.py
Received diff content from Anthropic for file: project/api/llama_stack/apis/inference/inference.py
Diff for error pattern 20 has been saved to error-bot/code-test/diff_inference_py.patch
Full output has been saved to error-bot/code-test/full_output_inference_py.txt
Patch applied successfully for file: project/api/llama_stack/apis/inference/inference.py
Modified content has been saved to /Users/nehal/Documents/Code/Golden-PR-Dataset/project/api/llama_stack/apis/inference/inference.py
Received diff content from Anthropic for file: project/api/llama_stack/providers/adapters/telemetry/opentelemetry/opentelemetry.py
Diff for error pattern 20 has been saved to error-bot/code-test/diff_opentelemetry_py.patch
Full output has been saved to error-bot/code-test/full_output_opentelemetry_py.txt
Patch applied successfully for file: project/api/llama_stack/providers/adapters/telemetry/opentelemetry/opentelemetry.py
Modified content has been saved to /Users/nehal/Documents/Code/Golden-PR-Dataset/project/api/llama_stack/providers/adapters/telemetry/opentelemetry/opentelemetry.py
Creating new git branch: error-20-api
Successfully created branch: error-20-api
Committing changes to file: project/api/llama_stack/apis/batch_inference/batch_inference.py
Changes to be committed:
project/api/llama_stack/apis/batch_inference/batch_inference.py | 4 ++--
 1 file changed, 2 insertions(+), 2 deletions(-)
Successfully committed changes: [main d7497546] Add error pattern 20 to multiple files
 1 file changed, 2 insertions(+), 2 deletions(-)
Committing changes to file: project/api/llama_stack/apis/inference/inference.py
Changes to be committed:
project/api/llama_stack/apis/inference/inference.py | 4 ++--
 1 file changed, 2 insertions(+), 2 deletions(-)
Successfully committed changes: [main 31c95be0] Add error pattern 20 to multiple files
 1 file changed, 2 insertions(+), 2 deletions(-)
Committing changes to file: project/api/llama_stack/providers/adapters/telemetry/opentelemetry/opentelemetry.py
Changes to be committed:
.../providers/adapters/telemetry/opentelemetry/opentelemetry.py   | 8 ++++----
 1 file changed, 4 insertions(+), 4 deletions(-)
Successfully committed changes: [main 5d8a8403] Add error pattern 20 to multiple files
 1 file changed, 4 insertions(+), 4 deletions(-)
Error pattern 20 has been added to 3 files in branch error-20-api
Last commit: 5d8a8403 Add error pattern 20 to multiple files


==================================================
BRANCH CREATED: error-20-api
==================================================

Modified files:
  - project/api/llama_stack/apis/batch_inference/batch_inference.py
  - project/api/llama_stack/apis/inference/inference.py
  - project/api/llama_stack/providers/adapters/telemetry/opentelemetry/opentelemetry.py

Diff files:
  - error-bot/code-test/diff_batch_inference_py.patch
  - error-bot/code-test/diff_inference_py.patch
  - error-bot/code-test/diff_opentelemetry_py.patch

Full output files:
  - error-bot/code-test/full_output_batch_inference_py.txt
  - error-bot/code-test/full_output_inference_py.txt
  - error-bot/code-test/full_output_opentelemetry_py.txt

Last commit:
  5d8a8403 Add error pattern 20 to multiple files
User input: 

Processing row 14 of 30

==================================================
Processing Error Pattern 27
Description: Subtle issues with recursive algorithms
Files to modify: ['project/api/llama_stack/providers/impls/ios/inference/LocalInferenceImpl/LocalInference.swift', 'project/api/llama_stack/providers/impls/ios/inference/LocalInferenceImpl/Parsing.swift', 'project/api/llama_stack/apis/inference/inference.py']
==================================================
Executing command: python error-bot/bot.py project/api/llama_stack/providers/impls/ios/inference/LocalInferenceImpl/LocalInference.swift project/api/llama_stack/providers/impls/ios/inference/LocalInferenceImpl/Parsing.swift project/api/llama_stack/apis/inference/inference.py 27 --commit --multi-file
Bot output:
Starting main function with file_paths: ['project/api/llama_stack/providers/impls/ios/inference/LocalInferenceImpl/LocalInference.swift', 'project/api/llama_stack/providers/impls/ios/inference/LocalInferenceImpl/Parsing.swift', 'project/api/llama_stack/apis/inference/inference.py'], error_number: 27, commit_to_branch: True, multi_file: True
Handling multi-file errors for files: ['project/api/llama_stack/providers/impls/ios/inference/LocalInferenceImpl/LocalInference.swift', 'project/api/llama_stack/providers/impls/ios/inference/LocalInferenceImpl/Parsing.swift', 'project/api/llama_stack/apis/inference/inference.py'] with error number: 27
Creating messages for Anthropic model...
Sending request to Anthropic model...
Error: Could not find diff tags in the response for file: project/api/llama_stack/providers/impls/ios/inference/LocalInferenceImpl/LocalInference.swift
Received diff content from Anthropic for file: project/api/llama_stack/providers/impls/ios/inference/LocalInferenceImpl/Parsing.swift
Diff for error pattern 27 has been saved to error-bot/code-test/diff_Parsing_swift.patch
Full output has been saved to error-bot/code-test/full_output_Parsing_swift.txt
Error: Failed to apply the patch for file: project/api/llama_stack/providers/impls/ios/inference/LocalInferenceImpl/Parsing.swift
Error: Could not find diff tags in the response for file: project/api/llama_stack/apis/inference/inference.py
No files were successfully modified. Skipping branch creation and commit.


WARNING: No branch information found in the output.

Modified files:
  - project/api/llama_stack/providers/impls/ios/inference/LocalInferenceImpl/LocalInference.swift
  - project/api/llama_stack/providers/impls/ios/inference/LocalInferenceImpl/Parsing.swift
  - project/api/llama_stack/apis/inference/inference.py

Diff files:
  - error-bot/code-test/diff_LocalInference_swift.patch
  - error-bot/code-test/diff_Parsing_swift.patch
  - error-bot/code-test/diff_inference_py.patch

Full output files:
  - error-bot/code-test/full_output_LocalInference_swift.txt
  - error-bot/code-test/full_output_Parsing_swift.txt
  - error-bot/code-test/full_output_inference_py.txt

WARNING: No commit information found in the output.
User input: r
Retrying current error...

==================================================
Processing Error Pattern 27
Description: Subtle issues with recursive algorithms
Files to modify: ['project/api/llama_stack/providers/impls/ios/inference/LocalInferenceImpl/LocalInference.swift', 'project/api/llama_stack/providers/impls/ios/inference/LocalInferenceImpl/Parsing.swift', 'project/api/llama_stack/apis/inference/inference.py']
==================================================
Executing command: python error-bot/bot.py project/api/llama_stack/providers/impls/ios/inference/LocalInferenceImpl/LocalInference.swift project/api/llama_stack/providers/impls/ios/inference/LocalInferenceImpl/Parsing.swift project/api/llama_stack/apis/inference/inference.py 27 --commit --multi-file
Bot output:
Starting main function with file_paths: ['project/api/llama_stack/providers/impls/ios/inference/LocalInferenceImpl/LocalInference.swift', 'project/api/llama_stack/providers/impls/ios/inference/LocalInferenceImpl/Parsing.swift', 'project/api/llama_stack/apis/inference/inference.py'], error_number: 27, commit_to_branch: True, multi_file: True
Handling multi-file errors for files: ['project/api/llama_stack/providers/impls/ios/inference/LocalInferenceImpl/LocalInference.swift', 'project/api/llama_stack/providers/impls/ios/inference/LocalInferenceImpl/Parsing.swift', 'project/api/llama_stack/apis/inference/inference.py'] with error number: 27
Creating messages for Anthropic model...
Sending request to Anthropic model...
Error: Could not find diff tags in the response for file: project/api/llama_stack/providers/impls/ios/inference/LocalInferenceImpl/LocalInference.swift
Received diff content from Anthropic for file: project/api/llama_stack/providers/impls/ios/inference/LocalInferenceImpl/Parsing.swift
Diff for error pattern 27 has been saved to error-bot/code-test/diff_Parsing_swift.patch
Full output has been saved to error-bot/code-test/full_output_Parsing_swift.txt
Patch applied successfully for file: project/api/llama_stack/providers/impls/ios/inference/LocalInferenceImpl/Parsing.swift
Modified content has been saved to /Users/nehal/Documents/Code/Golden-PR-Dataset/project/api/llama_stack/providers/impls/ios/inference/LocalInferenceImpl/Parsing.swift
Error: Could not find diff tags in the response for file: project/api/llama_stack/apis/inference/inference.py
Creating new git branch: error-27-api
Successfully created branch: error-27-api
Committing changes to file: project/api/llama_stack/providers/impls/ios/inference/LocalInferenceImpl/Parsing.swift
Changes to be committed:
.../impls/ios/inference/LocalInferenceImpl/Parsing.swift      | 11 +++++------
 1 file changed, 5 insertions(+), 6 deletions(-)
Successfully committed changes: [main f34a77a5] Add error pattern 27 to multiple files
 1 file changed, 5 insertions(+), 6 deletions(-)
Error pattern 27 has been added to 1 files in branch error-27-api
Last commit: f34a77a5 Add error pattern 27 to multiple files


==================================================
BRANCH CREATED: error-27-api
==================================================

Modified files:
  - project/api/llama_stack/providers/impls/ios/inference/LocalInferenceImpl/LocalInference.swift
  - project/api/llama_stack/providers/impls/ios/inference/LocalInferenceImpl/Parsing.swift
  - project/api/llama_stack/apis/inference/inference.py

Diff files:
  - error-bot/code-test/diff_LocalInference_swift.patch
  - error-bot/code-test/diff_Parsing_swift.patch
  - error-bot/code-test/diff_inference_py.patch

Full output files:
  - error-bot/code-test/full_output_LocalInference_swift.txt
  - error-bot/code-test/full_output_Parsing_swift.txt
  - error-bot/code-test/full_output_inference_py.txt

Last commit:
  f34a77a5 Add error pattern 27 to multiple files
User input: 

Processing row 15 of 30

==================================================
Processing Error Pattern 41
Description: Improper implementations of caching invalidation strategies
Files to modify: ['project/api/llama_stack/apis/memory_banks/memory_banks.py', 'project/api/llama_stack/providers/adapters/memory/qdrant/qdrant.py', 'project/api/llama_stack/providers/adapters/memory/pgvector/pgvector.py', 'project/api/llama_stack/providers/impls/meta_reference/memory/faiss.py']
==================================================
Executing command: python error-bot/bot.py project/api/llama_stack/apis/memory_banks/memory_banks.py project/api/llama_stack/providers/adapters/memory/qdrant/qdrant.py project/api/llama_stack/providers/adapters/memory/pgvector/pgvector.py project/api/llama_stack/providers/impls/meta_reference/memory/faiss.py 41 --commit --multi-file
Error processing row 15: Command '['python', 'error-bot/bot.py', 'project/api/llama_stack/apis/memory_banks/memory_banks.py', 'project/api/llama_stack/providers/adapters/memory/qdrant/qdrant.py', 'project/api/llama_stack/providers/adapters/memory/pgvector/pgvector.py', 'project/api/llama_stack/providers/impls/meta_reference/memory/faiss.py', '41', '--commit', '--multi-file']' returned non-zero exit status 1.
Error output:
Starting main function with file_paths: ['project/api/llama_stack/apis/memory_banks/memory_banks.py', 'project/api/llama_stack/providers/adapters/memory/qdrant/qdrant.py', 'project/api/llama_stack/providers/adapters/memory/pgvector/pgvector.py', 'project/api/llama_stack/providers/impls/meta_reference/memory/faiss.py'], error_number: 41, commit_to_branch: True, multi_file: True
Handling multi-file errors for files: ['project/api/llama_stack/apis/memory_banks/memory_banks.py', 'project/api/llama_stack/providers/adapters/memory/qdrant/qdrant.py', 'project/api/llama_stack/providers/adapters/memory/pgvector/pgvector.py', 'project/api/llama_stack/providers/impls/meta_reference/memory/faiss.py'] with error number: 41

User input: r
Retrying current error...

==================================================
Processing Error Pattern 41
Description: Improper implementations of caching invalidation strategies
Files to modify: ['project/api/llama_stack/apis/memory_banks/memory_banks.py', 'project/api/llama_stack/providers/adapters/memory/qdrant/qdrant.py', 'project/api/llama_stack/providers/adapters/memory/pgvector/pgvector.py', 'project/api/llama_stack/providers/impls/meta_reference/memory/faiss.py']
==================================================
Executing command: python error-bot/bot.py project/api/llama_stack/apis/memory_banks/memory_banks.py project/api/llama_stack/providers/adapters/memory/qdrant/qdrant.py project/api/llama_stack/providers/adapters/memory/pgvector/pgvector.py project/api/llama_stack/providers/impls/meta_reference/memory/faiss.py 41 --commit --multi-file
Error processing row 15: Command '['python', 'error-bot/bot.py', 'project/api/llama_stack/apis/memory_banks/memory_banks.py', 'project/api/llama_stack/providers/adapters/memory/qdrant/qdrant.py', 'project/api/llama_stack/providers/adapters/memory/pgvector/pgvector.py', 'project/api/llama_stack/providers/impls/meta_reference/memory/faiss.py', '41', '--commit', '--multi-file']' returned non-zero exit status 1.
Error output:
Starting main function with file_paths: ['project/api/llama_stack/apis/memory_banks/memory_banks.py', 'project/api/llama_stack/providers/adapters/memory/qdrant/qdrant.py', 'project/api/llama_stack/providers/adapters/memory/pgvector/pgvector.py', 'project/api/llama_stack/providers/impls/meta_reference/memory/faiss.py'], error_number: 41, commit_to_branch: True, multi_file: True
Handling multi-file errors for files: ['project/api/llama_stack/apis/memory_banks/memory_banks.py', 'project/api/llama_stack/providers/adapters/memory/qdrant/qdrant.py', 'project/api/llama_stack/providers/adapters/memory/pgvector/pgvector.py', 'project/api/llama_stack/providers/impls/meta_reference/memory/faiss.py'] with error number: 41

User input: 

Processing row 16 of 30

==================================================
Processing Error Pattern 38
Description: Unintended consequences of code refactoring
Files to modify: ['project/api/llama_stack/apis/agents/agents.py', 'project/api/llama_stack/apis/scoring_functions/scoring_functions.py', 'project/api/llama_stack/apis/inference/inference.py', 'project/api/llama_stack/providers/adapters/safety/together/together.py', 'project/api/llama_stack/providers/adapters/telemetry/opentelemetry/opentelemetry.py']
==================================================
Executing command: python error-bot/bot.py project/api/llama_stack/apis/agents/agents.py project/api/llama_stack/apis/scoring_functions/scoring_functions.py project/api/llama_stack/apis/inference/inference.py project/api/llama_stack/providers/adapters/safety/together/together.py project/api/llama_stack/providers/adapters/telemetry/opentelemetry/opentelemetry.py 38 --commit --multi-file
Error processing row 16: Command '['python', 'error-bot/bot.py', 'project/api/llama_stack/apis/agents/agents.py', 'project/api/llama_stack/apis/scoring_functions/scoring_functions.py', 'project/api/llama_stack/apis/inference/inference.py', 'project/api/llama_stack/providers/adapters/safety/together/together.py', 'project/api/llama_stack/providers/adapters/telemetry/opentelemetry/opentelemetry.py', '38', '--commit', '--multi-file']' returned non-zero exit status 1.
Error output:
Starting main function with file_paths: ['project/api/llama_stack/apis/agents/agents.py', 'project/api/llama_stack/apis/scoring_functions/scoring_functions.py', 'project/api/llama_stack/apis/inference/inference.py', 'project/api/llama_stack/providers/adapters/safety/together/together.py', 'project/api/llama_stack/providers/adapters/telemetry/opentelemetry/opentelemetry.py'], error_number: 38, commit_to_branch: True, multi_file: True
Handling multi-file errors for files: ['project/api/llama_stack/apis/agents/agents.py', 'project/api/llama_stack/apis/scoring_functions/scoring_functions.py', 'project/api/llama_stack/apis/inference/inference.py', 'project/api/llama_stack/providers/adapters/safety/together/together.py', 'project/api/llama_stack/providers/adapters/telemetry/opentelemetry/opentelemetry.py'] with error number: 38

User input: 

Processing row 17 of 30

==================================================
Processing Error Pattern 16
Description: Incorrect assumptions about network behavior
Files to modify: ['project/api/llama_stack/distribution/server/server.py', 'project/api/llama_stack/distribution/routers/routing_tables.py', 'project/api/llama_stack/distribution/configure.py', 'project/api/llama_stack/distribution/build_container.sh']
==================================================
Executing command: python error-bot/bot.py project/api/llama_stack/distribution/server/server.py project/api/llama_stack/distribution/routers/routing_tables.py project/api/llama_stack/distribution/configure.py project/api/llama_stack/distribution/build_container.sh 16 --commit --multi-file
Bot output:
Starting main function with file_paths: ['project/api/llama_stack/distribution/server/server.py', 'project/api/llama_stack/distribution/routers/routing_tables.py', 'project/api/llama_stack/distribution/configure.py', 'project/api/llama_stack/distribution/build_container.sh'], error_number: 16, commit_to_branch: True, multi_file: True
Handling multi-file errors for files: ['project/api/llama_stack/distribution/server/server.py', 'project/api/llama_stack/distribution/routers/routing_tables.py', 'project/api/llama_stack/distribution/configure.py', 'project/api/llama_stack/distribution/build_container.sh'] with error number: 16
Creating messages for Anthropic model...
Sending request to Anthropic model...
Received diff content from Anthropic for file: project/api/llama_stack/distribution/server/server.py
Diff for error pattern 16 has been saved to error-bot/code-test/diff_server_py.patch
Full output has been saved to error-bot/code-test/full_output_server_py.txt
Error: Failed to apply the patch for file: project/api/llama_stack/distribution/server/server.py
Received diff content from Anthropic for file: project/api/llama_stack/distribution/routers/routing_tables.py
Diff for error pattern 16 has been saved to error-bot/code-test/diff_routing_tables_py.patch
Full output has been saved to error-bot/code-test/full_output_routing_tables_py.txt
Error: Failed to apply the patch for file: project/api/llama_stack/distribution/routers/routing_tables.py
Error: Could not find diff tags in the response for file: project/api/llama_stack/distribution/configure.py
Received diff content from Anthropic for file: project/api/llama_stack/distribution/build_container.sh
Diff for error pattern 16 has been saved to error-bot/code-test/diff_build_container_sh.patch
Full output has been saved to error-bot/code-test/full_output_build_container_sh.txt
Patch applied successfully for file: project/api/llama_stack/distribution/build_container.sh
Modified content has been saved to /Users/nehal/Documents/Code/Golden-PR-Dataset/project/api/llama_stack/distribution/build_container.sh
Creating new git branch: error-16-api
Successfully created branch: error-16-api
Committing changes to file: project/api/llama_stack/distribution/build_container.sh
Changes to be committed:
project/api/llama_stack/distribution/build_container.sh | 6 +-----
 1 file changed, 1 insertion(+), 5 deletions(-)
Successfully committed changes: [main a621d51a] Add error pattern 16 to multiple files
 1 file changed, 1 insertion(+), 5 deletions(-)
Error pattern 16 has been added to 1 files in branch error-16-api
Last commit: a621d51a Add error pattern 16 to multiple files


==================================================
BRANCH CREATED: error-16-api
==================================================

Modified files:
  - project/api/llama_stack/distribution/server/server.py
  - project/api/llama_stack/distribution/routers/routing_tables.py
  - project/api/llama_stack/distribution/configure.py
  - project/api/llama_stack/distribution/build_container.sh

Diff files:
  - error-bot/code-test/diff_server_py.patch
  - error-bot/code-test/diff_routing_tables_py.patch
  - error-bot/code-test/diff_configure_py.patch
  - error-bot/code-test/diff_build_container_sh.patch

Full output files:
  - error-bot/code-test/full_output_server_py.txt
  - error-bot/code-test/full_output_routing_tables_py.txt
  - error-bot/code-test/full_output_configure_py.txt
  - error-bot/code-test/full_output_build_container_sh.txt

Last commit:
  a621d51a Add error pattern 16 to multiple files
User input: 

Processing row 18 of 30

==================================================
Processing Error Pattern 50
Description: Unintended consequences of using third-party libraries
Files to modify: ['project/api/llama_stack/providers/adapters/inference/fireworks', 'project/api/llama_stack/providers/adapters/inference/ollama/ollama.py', 'project/api/llama_stack/providers/adapters/inference/databricks/databricks.py', 'project/api/llama_stack/apis/inference/inference.py']
==================================================
Executing command: python error-bot/bot.py project/api/llama_stack/providers/adapters/inference/fireworks project/api/llama_stack/providers/adapters/inference/ollama/ollama.py project/api/llama_stack/providers/adapters/inference/databricks/databricks.py project/api/llama_stack/apis/inference/inference.py 50 --commit --multi-file
Error processing row 18: Command '['python', 'error-bot/bot.py', 'project/api/llama_stack/providers/adapters/inference/fireworks', 'project/api/llama_stack/providers/adapters/inference/ollama/ollama.py', 'project/api/llama_stack/providers/adapters/inference/databricks/databricks.py', 'project/api/llama_stack/apis/inference/inference.py', '50', '--commit', '--multi-file']' returned non-zero exit status 1.
Error output:
Starting main function with file_paths: ['project/api/llama_stack/providers/adapters/inference/fireworks', 'project/api/llama_stack/providers/adapters/inference/ollama/ollama.py', 'project/api/llama_stack/providers/adapters/inference/databricks/databricks.py', 'project/api/llama_stack/apis/inference/inference.py'], error_number: 50, commit_to_branch: True, multi_file: True
Handling multi-file errors for files: ['project/api/llama_stack/providers/adapters/inference/fireworks', 'project/api/llama_stack/providers/adapters/inference/ollama/ollama.py', 'project/api/llama_stack/providers/adapters/inference/databricks/databricks.py', 'project/api/llama_stack/apis/inference/inference.py'] with error number: 50

User input: r
Retrying current error...

==================================================
Processing Error Pattern 50
Description: Unintended consequences of using third-party libraries
Files to modify: ['project/api/llama_stack/providers/adapters/inference/fireworks', 'project/api/llama_stack/providers/adapters/inference/ollama/ollama.py', 'project/api/llama_stack/providers/adapters/inference/databricks/databricks.py', 'project/api/llama_stack/apis/inference/inference.py']
==================================================
Executing command: python error-bot/bot.py project/api/llama_stack/providers/adapters/inference/fireworks project/api/llama_stack/providers/adapters/inference/ollama/ollama.py project/api/llama_stack/providers/adapters/inference/databricks/databricks.py project/api/llama_stack/apis/inference/inference.py 50 --commit --multi-file
Error processing row 18: Command '['python', 'error-bot/bot.py', 'project/api/llama_stack/providers/adapters/inference/fireworks', 'project/api/llama_stack/providers/adapters/inference/ollama/ollama.py', 'project/api/llama_stack/providers/adapters/inference/databricks/databricks.py', 'project/api/llama_stack/apis/inference/inference.py', '50', '--commit', '--multi-file']' returned non-zero exit status 1.
Error output:
Starting main function with file_paths: ['project/api/llama_stack/providers/adapters/inference/fireworks', 'project/api/llama_stack/providers/adapters/inference/ollama/ollama.py', 'project/api/llama_stack/providers/adapters/inference/databricks/databricks.py', 'project/api/llama_stack/apis/inference/inference.py'], error_number: 50, commit_to_branch: True, multi_file: True
Handling multi-file errors for files: ['project/api/llama_stack/providers/adapters/inference/fireworks', 'project/api/llama_stack/providers/adapters/inference/ollama/ollama.py', 'project/api/llama_stack/providers/adapters/inference/databricks/databricks.py', 'project/api/llama_stack/apis/inference/inference.py'] with error number: 50

User input: 

Processing row 19 of 30

==================================================
Processing Error Pattern 48
Description: Subtle issues with database query optimization
Files to modify: ['project/api/llama_stack/apis/datasetio/datasetio.py', 'project/api/llama_stack/apis/batch_inference/batch_inference.py', 'project/api/llama_stack/apis/inference/inference.py', 'project/api/llama_stack/providers/adapters/telemetry/opentelemetry/opentelemetry.py']
==================================================
Executing command: python error-bot/bot.py project/api/llama_stack/apis/datasetio/datasetio.py project/api/llama_stack/apis/batch_inference/batch_inference.py project/api/llama_stack/apis/inference/inference.py project/api/llama_stack/providers/adapters/telemetry/opentelemetry/opentelemetry.py 48 --commit --multi-file
Error processing row 19: Command '['python', 'error-bot/bot.py', 'project/api/llama_stack/apis/datasetio/datasetio.py', 'project/api/llama_stack/apis/batch_inference/batch_inference.py', 'project/api/llama_stack/apis/inference/inference.py', 'project/api/llama_stack/providers/adapters/telemetry/opentelemetry/opentelemetry.py', '48', '--commit', '--multi-file']' returned non-zero exit status 1.
Error output:
Starting main function with file_paths: ['project/api/llama_stack/apis/datasetio/datasetio.py', 'project/api/llama_stack/apis/batch_inference/batch_inference.py', 'project/api/llama_stack/apis/inference/inference.py', 'project/api/llama_stack/providers/adapters/telemetry/opentelemetry/opentelemetry.py'], error_number: 48, commit_to_branch: True, multi_file: True
Handling multi-file errors for files: ['project/api/llama_stack/apis/datasetio/datasetio.py', 'project/api/llama_stack/apis/batch_inference/batch_inference.py', 'project/api/llama_stack/apis/inference/inference.py', 'project/api/llama_stack/providers/adapters/telemetry/opentelemetry/opentelemetry.py'] with error number: 48

User input: 

Processing row 20 of 30

==================================================
Processing Error Pattern 13
Description: Unintended side effects in pure functions
Files to modify: ['project/api/llama_stack/providers/impls/meta_reference/agents/agents.py', 'project/api/llama_stack/providers/impls/meta_reference/agents/tests/test_chat_agent.py', 'project/api/llama_stack/apis/agents/agents.py', 'project/api/llama_stack/apis/agents/client.py']
==================================================
Executing command: python error-bot/bot.py project/api/llama_stack/providers/impls/meta_reference/agents/agents.py project/api/llama_stack/providers/impls/meta_reference/agents/tests/test_chat_agent.py project/api/llama_stack/apis/agents/agents.py project/api/llama_stack/apis/agents/client.py 13 --commit --multi-file
Bot output:
Starting main function with file_paths: ['project/api/llama_stack/providers/impls/meta_reference/agents/agents.py', 'project/api/llama_stack/providers/impls/meta_reference/agents/tests/test_chat_agent.py', 'project/api/llama_stack/apis/agents/agents.py', 'project/api/llama_stack/apis/agents/client.py'], error_number: 13, commit_to_branch: True, multi_file: True
Handling multi-file errors for files: ['project/api/llama_stack/providers/impls/meta_reference/agents/agents.py', 'project/api/llama_stack/providers/impls/meta_reference/agents/tests/test_chat_agent.py', 'project/api/llama_stack/apis/agents/agents.py', 'project/api/llama_stack/apis/agents/client.py'] with error number: 13
Creating messages for Anthropic model...
Sending request to Anthropic model...
Received diff content from Anthropic for file: project/api/llama_stack/providers/impls/meta_reference/agents/agents.py
Diff for error pattern 13 has been saved to error-bot/code-test/diff_agents_py.patch
Full output has been saved to error-bot/code-test/full_output_agents_py.txt
Error: Failed to apply the patch for file: project/api/llama_stack/providers/impls/meta_reference/agents/agents.py
Error: Could not find diff tags in the response for file: project/api/llama_stack/providers/impls/meta_reference/agents/tests/test_chat_agent.py
Received diff content from Anthropic for file: project/api/llama_stack/apis/agents/agents.py
Diff for error pattern 13 has been saved to error-bot/code-test/diff_agents_py.patch
Full output has been saved to error-bot/code-test/full_output_agents_py.txt
Error: Failed to apply the patch for file: project/api/llama_stack/apis/agents/agents.py
Received diff content from Anthropic for file: project/api/llama_stack/apis/agents/client.py
Diff for error pattern 13 has been saved to error-bot/code-test/diff_client_py.patch
Full output has been saved to error-bot/code-test/full_output_client_py.txt
Patch applied successfully for file: project/api/llama_stack/apis/agents/client.py
Modified content has been saved to /Users/nehal/Documents/Code/Golden-PR-Dataset/project/api/llama_stack/apis/agents/client.py
Creating new git branch: error-13-api
Successfully created branch: error-13-api
Committing changes to file: project/api/llama_stack/apis/agents/client.py
Changes to be committed:
project/api/llama_stack/apis/agents/client.py | 6 +++++-
 1 file changed, 5 insertions(+), 1 deletion(-)
Successfully committed changes: [main 822064fd] Add error pattern 13 to multiple files
 1 file changed, 5 insertions(+), 1 deletion(-)
Error pattern 13 has been added to 1 files in branch error-13-api
Last commit: 822064fd Add error pattern 13 to multiple files


==================================================
BRANCH CREATED: error-13-api
==================================================

Modified files:
  - project/api/llama_stack/providers/impls/meta_reference/agents/agents.py
  - project/api/llama_stack/providers/impls/meta_reference/agents/tests/test_chat_agent.py
  - project/api/llama_stack/apis/agents/agents.py
  - project/api/llama_stack/apis/agents/client.py

Diff files:
  - error-bot/code-test/diff_agents_py.patch
  - error-bot/code-test/diff_test_chat_agent_py.patch
  - error-bot/code-test/diff_agents_py.patch
  - error-bot/code-test/diff_client_py.patch

Full output files:
  - error-bot/code-test/full_output_agents_py.txt
  - error-bot/code-test/full_output_test_chat_agent_py.txt
  - error-bot/code-test/full_output_agents_py.txt
  - error-bot/code-test/full_output_client_py.txt

Last commit:
  822064fd Add error pattern 13 to multiple files
User input: 

Processing row 21 of 30

==================================================
Processing Error Pattern 31
Description: Incorrect handling of unicode characters in model responses
Files to modify: ['project/api/llama_stack/providers/adapters/inference/ollama/ollama.py']
==================================================
Executing command: python error-bot/bot.py project/api/llama_stack/providers/adapters/inference/ollama/ollama.py 31 --commit
Bot output:
Starting main function with file_paths: ['project/api/llama_stack/providers/adapters/inference/ollama/ollama.py'], error_number: 31, commit_to_branch: True, multi_file: False
Processing single file: project/api/llama_stack/providers/adapters/inference/ollama/ollama.py with error number: 31
Sending request to Anthropic model...
Received diff content from Anthropic for file: project/api/llama_stack/providers/adapters/inference/ollama/ollama.py
Diff for error pattern 31 has been saved to error-bot/code-test/diff_ollama_py.patch
Full output has been saved to error-bot/code-test/full_output_ollama_py.txt
Patch applied successfully for file: project/api/llama_stack/providers/adapters/inference/ollama/ollama.py
Creating new git branch: error-31-api
Successfully created branch: error-31-api
Committing changes to file: /Users/nehal/Documents/Code/Golden-PR-Dataset/project/api/llama_stack/providers/adapters/inference/ollama/ollama.py
Changes to be committed:
project/api/llama_stack/providers/adapters/inference/ollama/ollama.py | 3 ++-
 1 file changed, 2 insertions(+), 1 deletion(-)
Successfully committed changes: [main 80029809] Add error pattern 31 in ollama.py
 1 file changed, 2 insertions(+), 1 deletion(-)
Error pattern 31 has been added to /Users/nehal/Documents/Code/Golden-PR-Dataset/project/api/llama_stack/providers/adapters/inference/ollama/ollama.py in branch error-31-api
Last commit: 80029809 Add error pattern 31 in ollama.py


==================================================
BRANCH CREATED: error-31-api
==================================================

Modified files:
  - project/api/llama_stack/providers/adapters/inference/ollama/ollama.py

Diff files:
  - error-bot/code-test/diff_ollama_py.patch

Full output files:
  - error-bot/code-test/full_output_ollama_py.txt

Last commit:
  80029809 Add error pattern 31 in ollama.py
User input: 

Processing row 22 of 30

==================================================
Processing Error Pattern 35
Description: Improper handling of database connection pooling
Files to modify: ['project/api/llama_stack/providers/adapters/memory/pgvector/pgvector.py']
==================================================
Executing command: python error-bot/bot.py project/api/llama_stack/providers/adapters/memory/pgvector/pgvector.py 35 --commit
Bot output:
Starting main function with file_paths: ['project/api/llama_stack/providers/adapters/memory/pgvector/pgvector.py'], error_number: 35, commit_to_branch: True, multi_file: False
Processing single file: project/api/llama_stack/providers/adapters/memory/pgvector/pgvector.py with error number: 35
Sending request to Anthropic model...
Received diff content from Anthropic for file: project/api/llama_stack/providers/adapters/memory/pgvector/pgvector.py
Diff for error pattern 35 has been saved to error-bot/code-test/diff_pgvector_py.patch
Full output has been saved to error-bot/code-test/full_output_pgvector_py.txt
Patch applied successfully for file: project/api/llama_stack/providers/adapters/memory/pgvector/pgvector.py
Creating new git branch: error-35-api
Successfully created branch: error-35-api
Committing changes to file: /Users/nehal/Documents/Code/Golden-PR-Dataset/project/api/llama_stack/providers/adapters/memory/pgvector/pgvector.py
Changes to be committed:
.../providers/adapters/memory/pgvector/pgvector.py | 39 ++++++++++++++++------
 1 file changed, 28 insertions(+), 11 deletions(-)
Successfully committed changes: [main 50697190] Add error pattern 35 in pgvector.py
 1 file changed, 28 insertions(+), 11 deletions(-)
Error pattern 35 has been added to /Users/nehal/Documents/Code/Golden-PR-Dataset/project/api/llama_stack/providers/adapters/memory/pgvector/pgvector.py in branch error-35-api
Last commit: 50697190 Add error pattern 35 in pgvector.py


==================================================
BRANCH CREATED: error-35-api
==================================================

Modified files:
  - project/api/llama_stack/providers/adapters/memory/pgvector/pgvector.py

Diff files:
  - error-bot/code-test/diff_pgvector_py.patch

Full output files:
  - error-bot/code-test/full_output_pgvector_py.txt

Last commit:
  50697190 Add error pattern 35 in pgvector.py
User input: 

Processing row 23 of 30

==================================================
Processing Error Pattern 11
Description: Subtle security vulnerabilities (e.g. timing attacks)
Files to modify: ['project/api/llama_stack/providers/adapters/safety/together/together.py']
==================================================
Executing command: python error-bot/bot.py project/api/llama_stack/providers/adapters/safety/together/together.py 11 --commit
Bot output:
Starting main function with file_paths: ['project/api/llama_stack/providers/adapters/safety/together/together.py'], error_number: 11, commit_to_branch: True, multi_file: False
Processing single file: project/api/llama_stack/providers/adapters/safety/together/together.py with error number: 11
Sending request to Anthropic model...
Received diff content from Anthropic for file: project/api/llama_stack/providers/adapters/safety/together/together.py
Diff for error pattern 11 has been saved to error-bot/code-test/diff_together_py.patch
Full output has been saved to error-bot/code-test/full_output_together_py.txt
Error: Failed to apply the patch for file: project/api/llama_stack/providers/adapters/safety/together/together.py


WARNING: No branch information found in the output.

Modified files:
  - project/api/llama_stack/providers/adapters/safety/together/together.py

Diff files:
  - error-bot/code-test/diff_together_py.patch

Full output files:
  - error-bot/code-test/full_output_together_py.txt

WARNING: No commit information found in the output.
User input: r
Retrying current error...

==================================================
Processing Error Pattern 11
Description: Subtle security vulnerabilities (e.g. timing attacks)
Files to modify: ['project/api/llama_stack/providers/adapters/safety/together/together.py']
==================================================
Executing command: python error-bot/bot.py project/api/llama_stack/providers/adapters/safety/together/together.py 11 --commit
Bot output:
Starting main function with file_paths: ['project/api/llama_stack/providers/adapters/safety/together/together.py'], error_number: 11, commit_to_branch: True, multi_file: False
Processing single file: project/api/llama_stack/providers/adapters/safety/together/together.py with error number: 11
Sending request to Anthropic model...
Received diff content from Anthropic for file: project/api/llama_stack/providers/adapters/safety/together/together.py
Diff for error pattern 11 has been saved to error-bot/code-test/diff_together_py.patch
Full output has been saved to error-bot/code-test/full_output_together_py.txt
Error: Failed to apply the patch for file: project/api/llama_stack/providers/adapters/safety/together/together.py


WARNING: No branch information found in the output.

Modified files:
  - project/api/llama_stack/providers/adapters/safety/together/together.py

Diff files:
  - error-bot/code-test/diff_together_py.patch

Full output files:
  - error-bot/code-test/full_output_together_py.txt

WARNING: No commit information found in the output.
User input: r
Retrying current error...

==================================================
Processing Error Pattern 11
Description: Subtle security vulnerabilities (e.g. timing attacks)
Files to modify: ['project/api/llama_stack/providers/adapters/safety/together/together.py']
==================================================
Executing command: python error-bot/bot.py project/api/llama_stack/providers/adapters/safety/together/together.py 11 --commit
Bot output:
Starting main function with file_paths: ['project/api/llama_stack/providers/adapters/safety/together/together.py'], error_number: 11, commit_to_branch: True, multi_file: False
Processing single file: project/api/llama_stack/providers/adapters/safety/together/together.py with error number: 11
Sending request to Anthropic model...
Received diff content from Anthropic for file: project/api/llama_stack/providers/adapters/safety/together/together.py
Diff for error pattern 11 has been saved to error-bot/code-test/diff_together_py.patch
Full output has been saved to error-bot/code-test/full_output_together_py.txt
Error: Failed to apply the patch for file: project/api/llama_stack/providers/adapters/safety/together/together.py


WARNING: No branch information found in the output.

Modified files:
  - project/api/llama_stack/providers/adapters/safety/together/together.py

Diff files:
  - error-bot/code-test/diff_together_py.patch

Full output files:
  - error-bot/code-test/full_output_together_py.txt

WARNING: No commit information found in the output.
User input: 

Processing row 24 of 30

==================================================
Processing Error Pattern 26
Description: Unintended consequences of lazy evaluation
Files to modify: ['project/api/llama_stack/apis/batch_inference/batch_inference.py', 'project/api/llama_stack/apis/inference/inference.py']
==================================================
Executing command: python error-bot/bot.py project/api/llama_stack/apis/batch_inference/batch_inference.py project/api/llama_stack/apis/inference/inference.py 26 --commit --multi-file
Bot output:
Starting main function with file_paths: ['project/api/llama_stack/apis/batch_inference/batch_inference.py', 'project/api/llama_stack/apis/inference/inference.py'], error_number: 26, commit_to_branch: True, multi_file: True
Handling multi-file errors for files: ['project/api/llama_stack/apis/batch_inference/batch_inference.py', 'project/api/llama_stack/apis/inference/inference.py'] with error number: 26
Creating messages for Anthropic model...
Sending request to Anthropic model...
Received diff content from Anthropic for file: project/api/llama_stack/apis/batch_inference/batch_inference.py
Diff for error pattern 26 has been saved to error-bot/code-test/diff_batch_inference_py.patch
Full output has been saved to error-bot/code-test/full_output_batch_inference_py.txt
Patch applied successfully for file: project/api/llama_stack/apis/batch_inference/batch_inference.py
Modified content has been saved to /Users/nehal/Documents/Code/Golden-PR-Dataset/project/api/llama_stack/apis/batch_inference/batch_inference.py
Received diff content from Anthropic for file: project/api/llama_stack/apis/inference/inference.py
Diff for error pattern 26 has been saved to error-bot/code-test/diff_inference_py.patch
Full output has been saved to error-bot/code-test/full_output_inference_py.txt
Patch applied successfully for file: project/api/llama_stack/apis/inference/inference.py
Modified content has been saved to /Users/nehal/Documents/Code/Golden-PR-Dataset/project/api/llama_stack/apis/inference/inference.py
Creating new git branch: error-26-api
Successfully created branch: error-26-api
Committing changes to file: project/api/llama_stack/apis/batch_inference/batch_inference.py
Changes to be committed:
project/api/llama_stack/apis/batch_inference/batch_inference.py | 2 +-
 1 file changed, 1 insertion(+), 1 deletion(-)
Successfully committed changes: [main bba1fa63] Add error pattern 26 to multiple files
 1 file changed, 1 insertion(+), 1 deletion(-)
Committing changes to file: project/api/llama_stack/apis/inference/inference.py
Changes to be committed:
project/api/llama_stack/apis/inference/inference.py | 6 +++---
 1 file changed, 3 insertions(+), 3 deletions(-)
Successfully committed changes: [main 4baa938f] Add error pattern 26 to multiple files
 1 file changed, 3 insertions(+), 3 deletions(-)
Error pattern 26 has been added to 2 files in branch error-26-api
Last commit: 4baa938f Add error pattern 26 to multiple files


==================================================
BRANCH CREATED: error-26-api
==================================================

Modified files:
  - project/api/llama_stack/apis/batch_inference/batch_inference.py
  - project/api/llama_stack/apis/inference/inference.py

Diff files:
  - error-bot/code-test/diff_batch_inference_py.patch
  - error-bot/code-test/diff_inference_py.patch

Full output files:
  - error-bot/code-test/full_output_batch_inference_py.txt
  - error-bot/code-test/full_output_inference_py.txt

Last commit:
  4baa938f Add error pattern 26 to multiple files
User input: 

Processing row 25 of 30

==================================================
Processing Error Pattern 29
Description: Improper implementations of state machines
Files to modify: ['project/api/llama_stack/providers/adapters/memory/qdrant/qdrant.py', 'project/api/llama_stack/providers/utils/memory/vector_store.py', 'project/api/llama_stack/apis/memory_banks/memory_banks.py']
==================================================
Executing command: python error-bot/bot.py project/api/llama_stack/providers/adapters/memory/qdrant/qdrant.py project/api/llama_stack/providers/utils/memory/vector_store.py project/api/llama_stack/apis/memory_banks/memory_banks.py 29 --commit --multi-file
Error processing row 25: Command '['python', 'error-bot/bot.py', 'project/api/llama_stack/providers/adapters/memory/qdrant/qdrant.py', 'project/api/llama_stack/providers/utils/memory/vector_store.py', 'project/api/llama_stack/apis/memory_banks/memory_banks.py', '29', '--commit', '--multi-file']' returned non-zero exit status 1.
Error output:
Starting main function with file_paths: ['project/api/llama_stack/providers/adapters/memory/qdrant/qdrant.py', 'project/api/llama_stack/providers/utils/memory/vector_store.py', 'project/api/llama_stack/apis/memory_banks/memory_banks.py'], error_number: 29, commit_to_branch: True, multi_file: True
Handling multi-file errors for files: ['project/api/llama_stack/providers/adapters/memory/qdrant/qdrant.py', 'project/api/llama_stack/providers/utils/memory/vector_store.py', 'project/api/llama_stack/apis/memory_banks/memory_banks.py'] with error number: 29

User input: r
Retrying current error...

==================================================
Processing Error Pattern 29
Description: Improper implementations of state machines
Files to modify: ['project/api/llama_stack/providers/adapters/memory/qdrant/qdrant.py', 'project/api/llama_stack/providers/utils/memory/vector_store.py', 'project/api/llama_stack/apis/memory_banks/memory_banks.py']
==================================================
Executing command: python error-bot/bot.py project/api/llama_stack/providers/adapters/memory/qdrant/qdrant.py project/api/llama_stack/providers/utils/memory/vector_store.py project/api/llama_stack/apis/memory_banks/memory_banks.py 29 --commit --multi-file
Error processing row 25: Command '['python', 'error-bot/bot.py', 'project/api/llama_stack/providers/adapters/memory/qdrant/qdrant.py', 'project/api/llama_stack/providers/utils/memory/vector_store.py', 'project/api/llama_stack/apis/memory_banks/memory_banks.py', '29', '--commit', '--multi-file']' returned non-zero exit status 1.
Error output:
Starting main function with file_paths: ['project/api/llama_stack/providers/adapters/memory/qdrant/qdrant.py', 'project/api/llama_stack/providers/utils/memory/vector_store.py', 'project/api/llama_stack/apis/memory_banks/memory_banks.py'], error_number: 29, commit_to_branch: True, multi_file: True
Handling multi-file errors for files: ['project/api/llama_stack/providers/adapters/memory/qdrant/qdrant.py', 'project/api/llama_stack/providers/utils/memory/vector_store.py', 'project/api/llama_stack/apis/memory_banks/memory_banks.py'] with error number: 29

User input: 

Processing row 26 of 30

==================================================
Processing Error Pattern 24
Description: Subtle issues with floating-point comparisons
Files to modify: ['project/api/llama_stack/providers/impls/ios/inference/LocalInferenceImpl/LocalInference.swift', 'project/api/llama_stack/providers/impls/ios/inference/LocalInferenceImpl/Parsing.swift']
==================================================
Executing command: python error-bot/bot.py project/api/llama_stack/providers/impls/ios/inference/LocalInferenceImpl/LocalInference.swift project/api/llama_stack/providers/impls/ios/inference/LocalInferenceImpl/Parsing.swift 24 --commit --multi-file
Bot output:
Starting main function with file_paths: ['project/api/llama_stack/providers/impls/ios/inference/LocalInferenceImpl/LocalInference.swift', 'project/api/llama_stack/providers/impls/ios/inference/LocalInferenceImpl/Parsing.swift'], error_number: 24, commit_to_branch: True, multi_file: True
Handling multi-file errors for files: ['project/api/llama_stack/providers/impls/ios/inference/LocalInferenceImpl/LocalInference.swift', 'project/api/llama_stack/providers/impls/ios/inference/LocalInferenceImpl/Parsing.swift'] with error number: 24
Creating messages for Anthropic model...
Sending request to Anthropic model...
Error: Could not find diff tags in the response for file: project/api/llama_stack/providers/impls/ios/inference/LocalInferenceImpl/LocalInference.swift
Received diff content from Anthropic for file: project/api/llama_stack/providers/impls/ios/inference/LocalInferenceImpl/Parsing.swift
Diff for error pattern 24 has been saved to error-bot/code-test/diff_Parsing_swift.patch
Full output has been saved to error-bot/code-test/full_output_Parsing_swift.txt
Error: Failed to apply the patch for file: project/api/llama_stack/providers/impls/ios/inference/LocalInferenceImpl/Parsing.swift
No files were successfully modified. Skipping branch creation and commit.


WARNING: No branch information found in the output.

Modified files:
  - project/api/llama_stack/providers/impls/ios/inference/LocalInferenceImpl/LocalInference.swift
  - project/api/llama_stack/providers/impls/ios/inference/LocalInferenceImpl/Parsing.swift

Diff files:
  - error-bot/code-test/diff_LocalInference_swift.patch
  - error-bot/code-test/diff_Parsing_swift.patch

Full output files:
  - error-bot/code-test/full_output_LocalInference_swift.txt
  - error-bot/code-test/full_output_Parsing_swift.txt

WARNING: No commit information found in the output.
User input: r
Retrying current error...

==================================================
Processing Error Pattern 24
Description: Subtle issues with floating-point comparisons
Files to modify: ['project/api/llama_stack/providers/impls/ios/inference/LocalInferenceImpl/LocalInference.swift', 'project/api/llama_stack/providers/impls/ios/inference/LocalInferenceImpl/Parsing.swift']
==================================================
Executing command: python error-bot/bot.py project/api/llama_stack/providers/impls/ios/inference/LocalInferenceImpl/LocalInference.swift project/api/llama_stack/providers/impls/ios/inference/LocalInferenceImpl/Parsing.swift 24 --commit --multi-file
Bot output:
Starting main function with file_paths: ['project/api/llama_stack/providers/impls/ios/inference/LocalInferenceImpl/LocalInference.swift', 'project/api/llama_stack/providers/impls/ios/inference/LocalInferenceImpl/Parsing.swift'], error_number: 24, commit_to_branch: True, multi_file: True
Handling multi-file errors for files: ['project/api/llama_stack/providers/impls/ios/inference/LocalInferenceImpl/LocalInference.swift', 'project/api/llama_stack/providers/impls/ios/inference/LocalInferenceImpl/Parsing.swift'] with error number: 24
Creating messages for Anthropic model...
Sending request to Anthropic model...
Error: Could not find diff tags in the response for file: project/api/llama_stack/providers/impls/ios/inference/LocalInferenceImpl/LocalInference.swift
Received diff content from Anthropic for file: project/api/llama_stack/providers/impls/ios/inference/LocalInferenceImpl/Parsing.swift
Diff for error pattern 24 has been saved to error-bot/code-test/diff_Parsing_swift.patch
Full output has been saved to error-bot/code-test/full_output_Parsing_swift.txt
Patch applied successfully for file: project/api/llama_stack/providers/impls/ios/inference/LocalInferenceImpl/Parsing.swift
Modified content has been saved to /Users/nehal/Documents/Code/Golden-PR-Dataset/project/api/llama_stack/providers/impls/ios/inference/LocalInferenceImpl/Parsing.swift
Creating new git branch: error-24-api
Successfully created branch: error-24-api
Committing changes to file: project/api/llama_stack/providers/impls/ios/inference/LocalInferenceImpl/Parsing.swift
Changes to be committed:
.../impls/ios/inference/LocalInferenceImpl/Parsing.swift          | 8 +++++++-
 1 file changed, 7 insertions(+), 1 deletion(-)
Successfully committed changes: [main 7ba11fa6] Add error pattern 24 to multiple files
 1 file changed, 7 insertions(+), 1 deletion(-)
Error pattern 24 has been added to 1 files in branch error-24-api
Last commit: 7ba11fa6 Add error pattern 24 to multiple files


==================================================
BRANCH CREATED: error-24-api
==================================================

Modified files:
  - project/api/llama_stack/providers/impls/ios/inference/LocalInferenceImpl/LocalInference.swift
  - project/api/llama_stack/providers/impls/ios/inference/LocalInferenceImpl/Parsing.swift

Diff files:
  - error-bot/code-test/diff_LocalInference_swift.patch
  - error-bot/code-test/diff_Parsing_swift.patch

Full output files:
  - error-bot/code-test/full_output_LocalInference_swift.txt
  - error-bot/code-test/full_output_Parsing_swift.txt

Last commit:
  7ba11fa6 Add error pattern 24 to multiple files
User input: 

Processing row 27 of 30

==================================================
Processing Error Pattern 10
Description: Improper error handling in distributed systems
Files to modify: ['project/api/llama_stack/distribution/server/server.py', 'project/api/llama_stack/distribution/routers/routing_tables.py', 'project/api/llama_stack/distribution/configure.py']
==================================================
Executing command: python error-bot/bot.py project/api/llama_stack/distribution/server/server.py project/api/llama_stack/distribution/routers/routing_tables.py project/api/llama_stack/distribution/configure.py 10 --commit --multi-file
Bot output:
Starting main function with file_paths: ['project/api/llama_stack/distribution/server/server.py', 'project/api/llama_stack/distribution/routers/routing_tables.py', 'project/api/llama_stack/distribution/configure.py'], error_number: 10, commit_to_branch: True, multi_file: True
Handling multi-file errors for files: ['project/api/llama_stack/distribution/server/server.py', 'project/api/llama_stack/distribution/routers/routing_tables.py', 'project/api/llama_stack/distribution/configure.py'] with error number: 10
Creating messages for Anthropic model...
Sending request to Anthropic model...
Received diff content from Anthropic for file: project/api/llama_stack/distribution/server/server.py
Diff for error pattern 10 has been saved to error-bot/code-test/diff_server_py.patch
Full output has been saved to error-bot/code-test/full_output_server_py.txt
Patch applied successfully for file: project/api/llama_stack/distribution/server/server.py
Modified content has been saved to /Users/nehal/Documents/Code/Golden-PR-Dataset/project/api/llama_stack/distribution/server/server.py
Received diff content from Anthropic for file: project/api/llama_stack/distribution/routers/routing_tables.py
Diff for error pattern 10 has been saved to error-bot/code-test/diff_routing_tables_py.patch
Full output has been saved to error-bot/code-test/full_output_routing_tables_py.txt
Error: Failed to apply the patch for file: project/api/llama_stack/distribution/routers/routing_tables.py
Received diff content from Anthropic for file: project/api/llama_stack/distribution/configure.py
Diff for error pattern 10 has been saved to error-bot/code-test/diff_configure_py.patch
Full output has been saved to error-bot/code-test/full_output_configure_py.txt
Patch applied successfully for file: project/api/llama_stack/distribution/configure.py
Modified content has been saved to /Users/nehal/Documents/Code/Golden-PR-Dataset/project/api/llama_stack/distribution/configure.py
Creating new git branch: error-10-api
Successfully created branch: error-10-api
Committing changes to file: project/api/llama_stack/distribution/server/server.py
Changes to be committed:
project/api/llama_stack/distribution/server/server.py | 19 ++++---------------
 1 file changed, 4 insertions(+), 15 deletions(-)
Successfully committed changes: [main e403c4e7] Add error pattern 10 to multiple files
 1 file changed, 4 insertions(+), 15 deletions(-)
Committing changes to file: project/api/llama_stack/distribution/configure.py
Changes to be committed:
project/api/llama_stack/distribution/configure.py | 6 ++----
 1 file changed, 2 insertions(+), 4 deletions(-)
Successfully committed changes: [main 04a80c10] Add error pattern 10 to multiple files
 1 file changed, 2 insertions(+), 4 deletions(-)
Error pattern 10 has been added to 2 files in branch error-10-api
Last commit: 04a80c10 Add error pattern 10 to multiple files


==================================================
BRANCH CREATED: error-10-api
==================================================

Modified files:
  - project/api/llama_stack/distribution/server/server.py
  - project/api/llama_stack/distribution/routers/routing_tables.py
  - project/api/llama_stack/distribution/configure.py

Diff files:
  - error-bot/code-test/diff_server_py.patch
  - error-bot/code-test/diff_routing_tables_py.patch
  - error-bot/code-test/diff_configure_py.patch

Full output files:
  - error-bot/code-test/full_output_server_py.txt
  - error-bot/code-test/full_output_routing_tables_py.txt
  - error-bot/code-test/full_output_configure_py.txt

Last commit:
  04a80c10 Add error pattern 10 to multiple files
User input: 

Processing row 28 of 30

==================================================
Processing Error Pattern 47
Description: Improper handling of network packet fragmentation
Files to modify: ['project/api/llama_stack/providers/adapters/telemetry/opentelemetry/opentelemetry.py', 'project/api/llama_stack/apis/batch_inference/batch_inference.py', 'project/api/llama_stack/apis/inference/inference.py']
==================================================
Executing command: python error-bot/bot.py project/api/llama_stack/providers/adapters/telemetry/opentelemetry/opentelemetry.py project/api/llama_stack/apis/batch_inference/batch_inference.py project/api/llama_stack/apis/inference/inference.py 47 --commit --multi-file
Bot output:
Starting main function with file_paths: ['project/api/llama_stack/providers/adapters/telemetry/opentelemetry/opentelemetry.py', 'project/api/llama_stack/apis/batch_inference/batch_inference.py', 'project/api/llama_stack/apis/inference/inference.py'], error_number: 47, commit_to_branch: True, multi_file: True
Handling multi-file errors for files: ['project/api/llama_stack/providers/adapters/telemetry/opentelemetry/opentelemetry.py', 'project/api/llama_stack/apis/batch_inference/batch_inference.py', 'project/api/llama_stack/apis/inference/inference.py'] with error number: 47
Creating messages for Anthropic model...
Sending request to Anthropic model...
Received diff content from Anthropic for file: project/api/llama_stack/providers/adapters/telemetry/opentelemetry/opentelemetry.py
Diff for error pattern 47 has been saved to error-bot/code-test/diff_opentelemetry_py.patch
Full output has been saved to error-bot/code-test/full_output_opentelemetry_py.txt
Patch applied successfully for file: project/api/llama_stack/providers/adapters/telemetry/opentelemetry/opentelemetry.py
Modified content has been saved to /Users/nehal/Documents/Code/Golden-PR-Dataset/project/api/llama_stack/providers/adapters/telemetry/opentelemetry/opentelemetry.py
Error: Could not find diff tags in the response for file: project/api/llama_stack/apis/batch_inference/batch_inference.py
Received diff content from Anthropic for file: project/api/llama_stack/apis/inference/inference.py
Diff for error pattern 47 has been saved to error-bot/code-test/diff_inference_py.patch
Full output has been saved to error-bot/code-test/full_output_inference_py.txt
Error: Failed to apply the patch for file: project/api/llama_stack/apis/inference/inference.py
Creating new git branch: error-47-api
Successfully created branch: error-47-api
Committing changes to file: project/api/llama_stack/providers/adapters/telemetry/opentelemetry/opentelemetry.py
Changes to be committed:
.../adapters/telemetry/opentelemetry/opentelemetry.py | 19 +++++++++++++------
 1 file changed, 13 insertions(+), 6 deletions(-)
Successfully committed changes: [main afd82bdd] Add error pattern 47 to multiple files
 1 file changed, 13 insertions(+), 6 deletions(-)
Error pattern 47 has been added to 1 files in branch error-47-api
Last commit: afd82bdd Add error pattern 47 to multiple files


==================================================
BRANCH CREATED: error-47-api
==================================================

Modified files:
  - project/api/llama_stack/providers/adapters/telemetry/opentelemetry/opentelemetry.py
  - project/api/llama_stack/apis/batch_inference/batch_inference.py
  - project/api/llama_stack/apis/inference/inference.py

Diff files:
  - error-bot/code-test/diff_opentelemetry_py.patch
  - error-bot/code-test/diff_batch_inference_py.patch
  - error-bot/code-test/diff_inference_py.patch

Full output files:
  - error-bot/code-test/full_output_opentelemetry_py.txt
  - error-bot/code-test/full_output_batch_inference_py.txt
  - error-bot/code-test/full_output_inference_py.txt

Last commit:
  afd82bdd Add error pattern 47 to multiple files
User input: 

Processing row 29 of 30

==================================================
Processing Error Pattern 34
Description: Incorrect implementations of custom hashing functions
Files to modify: ['project/api/llama_stack/providers/impls/meta_reference/memory/faiss.py', 'project/api/llama_stack/providers/utils/memory/vector_store.py']
==================================================
Executing command: python error-bot/bot.py project/api/llama_stack/providers/impls/meta_reference/memory/faiss.py project/api/llama_stack/providers/utils/memory/vector_store.py 34 --commit --multi-file
Bot output:
Starting main function with file_paths: ['project/api/llama_stack/providers/impls/meta_reference/memory/faiss.py', 'project/api/llama_stack/providers/utils/memory/vector_store.py'], error_number: 34, commit_to_branch: True, multi_file: True
Handling multi-file errors for files: ['project/api/llama_stack/providers/impls/meta_reference/memory/faiss.py', 'project/api/llama_stack/providers/utils/memory/vector_store.py'] with error number: 34
Creating messages for Anthropic model...
Sending request to Anthropic model...
Received diff content from Anthropic for file: project/api/llama_stack/providers/impls/meta_reference/memory/faiss.py
Diff for error pattern 34 has been saved to error-bot/code-test/diff_faiss_py.patch
Full output has been saved to error-bot/code-test/full_output_faiss_py.txt
Patch applied successfully for file: project/api/llama_stack/providers/impls/meta_reference/memory/faiss.py
Modified content has been saved to /Users/nehal/Documents/Code/Golden-PR-Dataset/project/api/llama_stack/providers/impls/meta_reference/memory/faiss.py
Received diff content from Anthropic for file: project/api/llama_stack/providers/utils/memory/vector_store.py
Diff for error pattern 34 has been saved to error-bot/code-test/diff_vector_store_py.patch
Full output has been saved to error-bot/code-test/full_output_vector_store_py.txt
Patch applied successfully for file: project/api/llama_stack/providers/utils/memory/vector_store.py
Modified content has been saved to /Users/nehal/Documents/Code/Golden-PR-Dataset/project/api/llama_stack/providers/utils/memory/vector_store.py
Creating new git branch: error-34-api
Successfully created branch: error-34-api
Committing changes to file: project/api/llama_stack/providers/impls/meta_reference/memory/faiss.py
Changes to be committed:
.../llama_stack/providers/impls/meta_reference/memory/faiss.py | 10 ++++++++++
 1 file changed, 10 insertions(+)
Successfully committed changes: [main 45d10237] Add error pattern 34 to multiple files
 1 file changed, 10 insertions(+)
Committing changes to file: project/api/llama_stack/providers/utils/memory/vector_store.py
Changes to be committed:
.../api/llama_stack/providers/utils/memory/vector_store.py    | 11 +++++++++++
 1 file changed, 11 insertions(+)
Successfully committed changes: [main 6f9b7c31] Add error pattern 34 to multiple files
 1 file changed, 11 insertions(+)
Error pattern 34 has been added to 2 files in branch error-34-api
Last commit: 6f9b7c31 Add error pattern 34 to multiple files


==================================================
BRANCH CREATED: error-34-api
==================================================

Modified files:
  - project/api/llama_stack/providers/impls/meta_reference/memory/faiss.py
  - project/api/llama_stack/providers/utils/memory/vector_store.py

Diff files:
  - error-bot/code-test/diff_faiss_py.patch
  - error-bot/code-test/diff_vector_store_py.patch

Full output files:
  - error-bot/code-test/full_output_faiss_py.txt
  - error-bot/code-test/full_output_vector_store_py.txt

Last commit:
  6f9b7c31 Add error pattern 34 to multiple files
User input: 

Processing row 30 of 30

==================================================
Processing Error Pattern 46
Description: Incorrect implementations of custom serialization/deserialization
Files to modify: ['project/api/llama_stack/apis/agents/agents.py', 'project/api/llama_stack/apis/agents/client.py', 'project/api/llama_stack/providers/impls/meta_reference/agents/agents.py', 'project/api/llama_stack/providers/impls/meta_reference/agents/tests/test_chat_agent.py']
==================================================
Executing command: python error-bot/bot.py project/api/llama_stack/apis/agents/agents.py project/api/llama_stack/apis/agents/client.py project/api/llama_stack/providers/impls/meta_reference/agents/agents.py project/api/llama_stack/providers/impls/meta_reference/agents/tests/test_chat_agent.py 46 --commit --multi-file
Bot output:
Starting main function with file_paths: ['project/api/llama_stack/apis/agents/agents.py', 'project/api/llama_stack/apis/agents/client.py', 'project/api/llama_stack/providers/impls/meta_reference/agents/agents.py', 'project/api/llama_stack/providers/impls/meta_reference/agents/tests/test_chat_agent.py'], error_number: 46, commit_to_branch: True, multi_file: True
Handling multi-file errors for files: ['project/api/llama_stack/apis/agents/agents.py', 'project/api/llama_stack/apis/agents/client.py', 'project/api/llama_stack/providers/impls/meta_reference/agents/agents.py', 'project/api/llama_stack/providers/impls/meta_reference/agents/tests/test_chat_agent.py'] with error number: 46
Creating messages for Anthropic model...
Sending request to Anthropic model...
Error: Could not find diff tags in the response for file: project/api/llama_stack/apis/agents/agents.py
Received diff content from Anthropic for file: project/api/llama_stack/apis/agents/client.py
Diff for error pattern 46 has been saved to error-bot/code-test/diff_client_py.patch
Full output has been saved to error-bot/code-test/full_output_client_py.txt
Patch applied successfully for file: project/api/llama_stack/apis/agents/client.py
Modified content has been saved to /Users/nehal/Documents/Code/Golden-PR-Dataset/project/api/llama_stack/apis/agents/client.py
Received diff content from Anthropic for file: project/api/llama_stack/providers/impls/meta_reference/agents/agents.py
Diff for error pattern 46 has been saved to error-bot/code-test/diff_agents_py.patch
Full output has been saved to error-bot/code-test/full_output_agents_py.txt
Patch applied successfully for file: project/api/llama_stack/providers/impls/meta_reference/agents/agents.py
Modified content has been saved to /Users/nehal/Documents/Code/Golden-PR-Dataset/project/api/llama_stack/providers/impls/meta_reference/agents/agents.py
Error: Could not find diff tags in the response for file: project/api/llama_stack/providers/impls/meta_reference/agents/tests/test_chat_agent.py
Creating new git branch: error-46-api
Successfully created branch: error-46-api
Committing changes to file: project/api/llama_stack/apis/agents/client.py
Changes to be committed:
project/api/llama_stack/apis/agents/client.py | 16 ++++++++++------
 1 file changed, 10 insertions(+), 6 deletions(-)
Successfully committed changes: [main 2faaba1c] Add error pattern 46 to multiple files
 1 file changed, 10 insertions(+), 6 deletions(-)
Committing changes to file: project/api/llama_stack/providers/impls/meta_reference/agents/agents.py
Changes to be committed:
.../impls/meta_reference/agents/agents.py          | 32 ++++++++++++----------
 1 file changed, 17 insertions(+), 15 deletions(-)
Successfully committed changes: [main d72ec091] Add error pattern 46 to multiple files
 1 file changed, 17 insertions(+), 15 deletions(-)
Error pattern 46 has been added to 2 files in branch error-46-api
Last commit: d72ec091 Add error pattern 46 to multiple files


==================================================
BRANCH CREATED: error-46-api
==================================================

Modified files:
  - project/api/llama_stack/apis/agents/agents.py
  - project/api/llama_stack/apis/agents/client.py
  - project/api/llama_stack/providers/impls/meta_reference/agents/agents.py
  - project/api/llama_stack/providers/impls/meta_reference/agents/tests/test_chat_agent.py

Diff files:
  - error-bot/code-test/diff_agents_py.patch
  - error-bot/code-test/diff_client_py.patch
  - error-bot/code-test/diff_agents_py.patch
  - error-bot/code-test/diff_test_chat_agent_py.patch

Full output files:
  - error-bot/code-test/full_output_agents_py.txt
  - error-bot/code-test/full_output_client_py.txt
  - error-bot/code-test/full_output_agents_py.txt
  - error-bot/code-test/full_output_test_chat_agent_py.txt

Last commit:
  d72ec091 Add error pattern 46 to multiple files
User input: 

All errors processed.
